# 围棋中的恐慌与恢复

> 原文:[https://golangbyexample.com/panic-and-recover-golang/](https://golangbyexample.com/panic-and-recover-golang/)

这是第 28 章，也是 golang 综合教程系列的最后一章。这是本系列其他章节的参考链接–[格朗综合教程系列](https://golangbyexample.com/golang-comprehensive-tutorial/)

**上一教程**–[错误-第 2 部分](https://golangbyexample.com/error-in-golang-advanced/)

现在让我们来看看当前的教程。下面是当前教程的目录。

# **概述**

戈朗的恐慌类似于例外。恐慌是指在异常情况下退出程序。程序中出现死机有两种方式

*   程序中的运行时错误
*   通过显式调用紧急函数。当程序无法继续并且必须退出时，程序员可以调用这个函数

Go 提供了一个特殊的功能来制造恐慌。下面是函数的语法

```
func panic(v interface{})
```

程序员可以显式调用这个函数来制造恐慌。它以一个空接口作为参数。当程序中出现恐慌时，它会输出两件事

*   作为参数传递给紧急函数的错误消息
*   恐慌发生的堆栈跟踪

# **运行时错误恐慌**

程序中的运行时错误可能在以下情况下发生

*   越界数组访问

*   在零指针上调用函数

*   在封闭信道上发送

*   不正确的类型断言

让我们看一个由越界数组访问引起的运行时错误的例子。

```
package main

import "fmt"

func main() {

	a := []string{"a", "b"}
	print(a, 2)
}

func print(a []string, index int) {
	fmt.Println(a[index])
}
```

**输出**

```
panic: runtime error: index out of range [2] with length 2

goroutine 1 [running]:
main.checkAndPrint(...)
        main.go:12
main.main()
        /main.go:8 +0x1b
exit status 2
```

在上面的程序中，我们有一个长度为 2 的切片，我们试图在**打印**功能中访问索引为 3 的切片。不允许越界访问，从输出中可以看出，这将造成恐慌。请注意，在输出中有两件事

*   错误消息
*   恐慌发生的堆栈跟踪

在很多情况下，程序中可能会发生运行时错误。我们不会提到所有这些，但你会明白的

# **明确调用恐慌功能**

程序员可以显式调用紧急函数的一些情况是:

*   该函数需要一个有效的参数，但是提供了一个零参数。在这种情况下，程序不能继续，它会引起一个通过零参数的恐慌

*   程序无法继续的任何其他情况。

我们来看一个例子。

```
package main

import "fmt"

func main() {

	a := []string{"a", "b"}
	checkAndPrint(a, 2)
}

func checkAndPrint(a []string, index int) {
	if index > (len(a) - 1) {
		panic("Out of bound access for slice")
	}
	fmt.Println(a[index])
}
```

**输出**

```
panic: Out of bound access for slice

goroutine 1 [running]:
main.checkAndPrint(0xc000104f58, 0x2, 0x2, 0x2)
      main.go:13 +0xe2
main.main()
        main.go:8 +0x7d
exit status 2
```

在上面的程序中，我们再次有一个函数 **checkAndPrint** ，它接受一个切片作为参数和一个索引。然后检查传递的索引是否大于切片长度减 1。如果是，那么它超出了切片的访问范围，因此它会死机。如果不是，则打印该索引处的值。再次注意，在输出中有两件事

*   错误消息

*   恐慌发生的堆栈跟踪

# **恐慌与推迟**

当在函数中引发恐慌时，该函数的执行停止，任何延迟的函数都将被执行。事实上，堆栈中所有函数调用的延迟函数也将被执行，直到所有函数都返回。届时，程序将退出，并打印紧急消息

因此，如果一个延迟函数存在，那么它将被执行，并且控制将被返回给调用者函数，调用者函数将再次执行它的延迟函数(如果存在的话)，并且该链继续进行，直到程序存在。

让我们看一个例子

```
package main
import "fmt"
func main() {
    defer fmt.Println("Defer in main")
    panic("Panic with Defer")
    fmt.Println("After painc in f2")
}
```

**输出**

```
Defer in main
panic: Panic Create

goroutine 1 [running]:
main.main()
        /Users/slohia/go/src/github.com/golang-examples/articles/tutorial/panicRecover/deferWithPanic/main.go:7 +0x95
exit status 2
```

在上面的程序中，我们首先有一个延迟函数，然后我们手动创建恐慌。正如您从输出中看到的那样，延迟函数被执行，如下行被打印在输出中

```
Defer in main
```

让我们理解当程序中发生恐慌时会发生什么。想象一下从**主**功能到 **f1** 功能再到 **f2** 功能的函数调用

**主**->T2【f1】->T4【F2】

现在假设恐慌发生在函数 **f2** 中，那么下面将是将要发生的一系列事件

*   将停止执行 **f2** 。如果存在，将执行 **f2** 中的延迟功能。控制将返回给呼叫者，这是一个功能 **f1** 。

*   **f1** 函数的行为类似于该函数中发生的恐慌，之后调用将返回给调用方，调用方是**主**函数。请注意，如果两者之间有更多的函数，那么该过程将以类似的方式继续向上堆栈

*   **main** 函数也将表现得好像在该函数中发生了恐慌，之后，程序将崩溃

*   一旦程序崩溃，它将打印紧急消息和堆栈跟踪

让我们来看一个节目

```
package main
import "fmt"
func main() {
    f1()
}
func f1() {
    defer fmt.Println("Defer in f1")
    f2()
    fmt.Println("After painc in f1")
}
func f2() {
    defer fmt.Println("Defer in f2")
    panic("Panic Demo")
    fmt.Println("After painc in f2")
}
```

**输出**

```
Defer in f2
Defer in f1
panic: Panic Demo

goroutine 1 [running]:
main.f2()
        main.go:17 +0x95
main.f1()
        main.go:11 +0x96
main.main()
        main.go:6 +0x20
exit status 2
```

在上面的程序中，像下面这样的 f2 函数发生了恐慌

```
panic("Panic Demo")
```

f2 中的 delay 函数在此之后被调用，并打印下面的消息

```
Defer in f2
```

请注意，一旦在 **f2** 函数中发生恐慌，如果 **f2** 从未被执行，那么它的执行将会在线下停止

```
fmt.Println("After painc in f2")
```

控制返回到 **f1** ，并且它具有延迟功能。延迟被执行，并打印下面的消息。

```
Defer in f1
```

此后，控制返回到主功能，然后程序崩溃。输出打印了紧急消息以及从 main 到 f1 到 f2 的整个堆栈跟踪。

# **收复戈朗**

Go 提供了一个内置功能 **recover** 用于从恐慌中恢复。下面是这个函数的签名

```
func recover() interface{}
```

上面我们已经了解到**延迟**函数是唯一在**恐慌**之后调用的函数。所以将**恢复**功能置于**延迟**功能中是有意义的。如果**恢复**功能不在延迟功能内，则不会停止**死机**。

让我们看一个恢复的例子

```
package main

import "fmt"

func main() {

	a := []string{"a", "b"}
	checkAndPrint(a, 2)
	fmt.Println("Exiting normally")
}

func checkAndPrint(a []string, index int) {
	defer handleOutOfBounds()
	if index > (len(a) - 1) {
		panic("Out of bound access for slice")
	}
	fmt.Println(a[index])
}

func handleOutOfBounds() {
	if r := recover(); r != nil {
		fmt.Println("Recovering from panic:", r)
	}
}
```

**输出**

```
Recovering from panic: Out of bound access for slice
Exiting normally
```

在上面的程序中，我们有一个函数 **checkAndPrint** ，它在参数中传递的索引处检查并打印切片元素。如果传递的索引大于数组的长度，程序就会死机。我们还在函数**的开始处添加了一个名为 **handleOutIfBounds** 的延迟函数**。该函数包含如下的恢复函数调用

```
if r := recover(); r != nil {
    fmt.Println("Recovering from panic:", r)
}
```

**恢复**功能会捕捉到恐慌，我们也可以打印恐慌的消息。

```
Recovering from panic: Out of bound access for slice
```

恢复功能后，程序继续，控制返回到被调用的功能，这里是**主**。这就是为什么我们的输出为

```
Exiting normally
```

恢复函数返回传递给紧急函数的值。因此，检查 recover 函数的返回值是一个很好的做法。如果返回值为零，则没有发生恐慌，并且没有用恐慌调用恢复函数。这就是为什么我们在延迟函数**中有下面的代码**

```
if r := recover(); r != nil 
```

这里如果 **r** 为零，那么恐慌就不会发生。因此，如果没有恐慌，那么呼吁恢复将返回零

请注意，如果延迟函数和恢复函数不是从恐慌函数中调用的，那么在这种情况下，恐慌也可以在被调用的函数中恢复。事实上，在调用栈链中，随后从恐慌中恢复是可能的。

让我们看一个例子

```
package main

import "fmt"

func main() {
    a := []string{"a", "b"}
    checkAndPrintWithRecover(a, 2)
    fmt.Println("Exiting normally")
}
func checkAndPrintWithRecover(a []string, index int) {
    defer handleOutOfBounds()
    checkAndPrint(a, 2)
}
func checkAndPrint(a []string, index int) {
    if index > (len(a) - 1) {
        panic("Out of bound access for slice")
    }
    fmt.Println(a[index])
}
func handleOutOfBounds() {
    if r := recover(); r != nil {
        fmt.Println("Recovering from panic:", r)
    }
}
```

**输出**

```
Recovering from panic: Out of bound access for slice
Exiting normally
```

除了我们有一个额外的函数**checkand printwistrecover**之外，上面的程序与前面的程序完全相同，它包含对

*   具有恢复功能的延迟功能，即**处理关闭**
*   调用**检查和打印**功能

**所以基本上 **checkAndPrint** 函数引发了恐慌但是没有 recover 函数相反调用 recover 在于 **checkAndPrintWithRecover** 函数。但是程序仍然能够从恐慌中恢复，因为恐慌也可以在被调用的函数中恢复，随后也可以在链中恢复**

 **我们在上面提到，如果恢复功能不在延迟功能内，那么它不会停止死机。

让我们看一个示例程序

```
package main

import "fmt"

func main() {

	a := []string{"a", "b"}
	checkAndPrint(a, 2)
	fmt.Println("Exiting normally")
}

func checkAndPrint(a []string, index int) {
	handleOutOfBounds()
	if index > (len(a) - 1) {
		panic("Out of bound access for slice")
	}
	fmt.Println(a[index])
}

func handleOutOfBounds() {
	if r := recover(); r != nil {
		fmt.Println("Recovering from panic:", r)
	}
}
```

**输出**

```
panic: Out of bound access for slice

goroutine 1 [running]:
main.checkAndPrint(0xc000104f58, 0x2, 0x2, 0x2)
        /Users/slohia/go/src/github.com/golang-examples/articles/tutorial/panicRecover/recoverNegativeExample/main.go:15 +0xea
main.main()
        /Users/slohia/go/src/github.com/golang-examples/articles/tutorial/panicRecover/recoverNegativeExample/main.go:8 +0x81
exit status 2
```

在上述程序中，恢复功能不在延迟功能内。从输出中可以看出，它不会停止恐慌，因此您可以看到上面的输出

# **【恐慌/恢复】和**

关于 be recover 函数需要注意的一点是，它只能恢复发生在同一个 goroutine 中的恐慌。如果恐慌发生在不同的地区，而复苏发生在不同的地区，那么恐慌不会停止。让我们看一个程序

```
package main
import "fmt"
func main() {
    a := []string{"a", "b"}
    checkAndPrintWithRecover(a, 2)
    time.Sleep(time.Second)
    fmt.Println("Exiting normally")
}
func checkAndPrintWithRecover(a []string, index int) {
    defer handleOutOfBounds()
    go checkAndPrint(a, 2)
}
func checkAndPrint(a []string, index int) {
    if index > (len(a) - 1) {
        panic("Out of bound access for slice")
    }
    fmt.Println(a[index])
}
func handleOutOfBounds() {
    if r := recover(); r != nil {
        fmt.Println("Recovering from panic:", r)
    }
}
```

**输出**

```
Exiting normally
panic: Out of bound access for slice

goroutine 18 [running]:
main.checkAndPrint(0xc0000a6020, 0x2, 0x2, 0x2)
        /Users/slohia/go/src/github.com/golang-examples/articles/tutorial/panicRecover/goroutine/main.go:19 +0xe2
created by main.checkAndPrintWithRecover
        /Users/slohia/go/src/github.com/golang-examples/articles/tutorial/panicRecover/goroutine/main.go:14 +0x82
exit status 2
```

在上面的程序中，我们在 goro tine 中有 **checkAndPrint** ，它在 goro tine 中引发**恐慌**。**恢复**功能在通话中。从输出中可以看出，它不会停止**恐慌**，因此可以看到上面的输出

# **打印叠加痕迹**

golang 的调试包还提供了 StackTrace 函数，可以用来打印恢复函数中死机的堆栈跟踪

```
package main
import (
    "fmt"
    "runtime/debug"
)
func main() {
    a := []string{"a", "b"}
    checkAndPrint(a, 2)
    fmt.Println("Exiting normally")
}
func checkAndPrint(a []string, index int) {
    defer handleOutOfBounds()
    if index > (len(a) - 1) {
        panic("Out of bound access for slice")
    }
    fmt.Println(a[index])
}
func handleOutOfBounds() {
    if r := recover(); r != nil {
        fmt.Println("Recovering from panic:", r)
        fmt.Println("Stack Trace:")
        debug.PrintStack()
    }
}
```

**输出**

```
Recovering from panic: Out of bound access for slice
Stack Trace:
goroutine 1 [running]:
runtime/debug.Stack(0xd, 0x0, 0x0)
        stack.go:24 +0x9d
runtime/debug.PrintStack()
        stack.go:16 +0x22
main.handleOutOfBounds()
        main.go:27 +0x10f
panic(0x10ab8c0, 0x10e8f60)
        /Users/slohia/Documents/goversion/go1.14.1/src/runtime/panic.go:967 +0x166
main.checkAndPrint(0xc000104f58, 0x2, 0x2, 0x2)
        main.go:18 +0x111
main.main()
        main.go:11 +0x81
Exiting normally
```

在上面的程序中，我们使用 **StackTrace** 函数打印恢复函数中死机的堆栈跟踪。从输出中可以看出，它打印了正确的堆栈跟踪

# **恐慌恢复时功能的返回值**

当恐慌恢复时，恐慌函数的返回值将是恐慌函数返回类型的默认值

让我们为它看一个程序

```
package main
import (
    "fmt"
)
func main() {
    a := []int{5, 6}
    val, err := checkAndGet(a, 2)
    fmt.Printf("Val: %d\n", val)
    fmt.Println("Error: ", err)
}
func checkAndGet(a []int, index int) (int, error) {
    defer handleOutOfBounds()
    if index > (len(a) - 1) {
        panic("Out of bound access for slice")
    }
    return a[index], nil
}
func handleOutOfBounds() {
    if r := recover(); r != nil {
        fmt.Println("Recovering from panic:", r)
    }
}
```

**输出**

```
Recovering from panic: Out of bound access for slice
Val: 0
Error: 
```

在上面的程序中，我们有**检查和获取**函数，该函数获取 int slice 中特定索引的值。如果传递给此函数的索引大于(slice-1 的长度)，则引发恐慌。还有一个 **handleOutOfBounds** 功能，用于从恐慌中恢复。因此，我们将索引 2 传递给**检查和获取**功能，它会引发恐慌，恐慌会在 **handleOutOfBounds** 功能中恢复。这就是为什么我们首先得到这个输出

```
Recovering from panic: Out of bound access for slice
```

请注意，在主函数中，我们像这样从**检查和获取**中回忆返回值

```
val, err := checkAndGet(a, 2)
```

**检查并获取**有两个返回值

*   （同 Internationalorganizations）国际组织
*   错误

由于**检查和获取**会产生恐慌，恐慌会在 handleOutOfBounds 函数中恢复，因此**检查和获取**的返回值将是其类型的默认值。

因此

```
 fmt.Printf("Val: %d\n", val)
```

输出

```
Val: 0
```

因为零是 **int** 类型的默认值。

和

```
fmt.Println("Error: ", err)
```

输出

```
Error: 
```

因为 nil 是**错误**类型的默认值。

如果不想返回类型的默认零值，那么可以使用命名返回值。让我们来看看这个节目。

```
package main
import (
    "fmt"
)
func main() {
    a := []int{5, 6}
    val, err := checkAndGet(a, 2)
    fmt.Printf("Val: %d\n", val)
    fmt.Println("Error: ", err)
}
func checkAndGet(a []int, index int) (value int, err error) {
    value = 10
    defer handleOutOfBounds()
    if index > (len(a) - 1) {
        panic("Out of bound access for slice")
    }
    value = a[index]
    return value, nil
}
func handleOutOfBounds() {
    if r := recover(); r != nil {
        fmt.Println("Recovering from panic:", r)
    }
}
```

**输出**

```
Recovering from panic: Out of bound access for slice
Val: 10
Error: 
```

这个程序和之前的程序一样，唯一的区别是我们在 **checkAndGet** 函数中使用了命名返回值。

```
func checkAndGet(a []int, index int) (value int, err error)
```

我们在**检查和获取**功能中将命名返回值设置为 10

```
value = 10
```

这就是为什么我们在这个程序中得到下面的输出，因为恐慌产生了，它被恢复了

```
Recovering from panic: Out of bound access for slice
Val: 10
Error: 
```

还要注意，如果在程序中不会产生恐慌，那么它会在索引处输出正确的值。

# **结论**

这就是戈朗的恐慌和复苏。希望你喜欢这篇文章。请在评论中分享反馈/改进/错误

**上一教程**–[错误-第 2 部分](https://golangbyexample.com/error-in-golang-advanced/)**