# 在围棋的不同功能中恢复恐慌

> 原文:[https://golangbyexample . com/recover-死机-不同功能-go/](https://golangbyexample.com/recover-panic-different-function-go/)

# **概述**

如果**延迟**功能和**恢复**功能没有从恐慌功能中调用，那么在这种情况下**恐慌**也可以在被调用的功能中恢复。事实上，在调用栈链中，随后从恐慌中恢复是可能的。

# **程序**

```
package main

import "fmt"

func main() {
    a := []string{"a", "b"}
    checkAndPrintWithRecover(a, 2)
    fmt.Println("Exiting normally")
}

func checkAndPrintWithRecover(a []string, index int) {
    defer handleOutOfBounds()
    checkAndPrint(a, 2)
}

func checkAndPrint(a []string, index int) {
    if index > (len(a) - 1) {
        panic("Out of bound access for slice")
    }
    fmt.Println(a[index])
}

func handleOutOfBounds() {
    if r := recover(); r != nil {
        fmt.Println("Recovering from panic:", r)
    }
}
```

**输出**

```
Recovering from panic: Out of bound access for slice
Exiting normally
```

在上面的程序中，我们有一个函数 **checkAndPrint** ，它在参数中传递的索引处检查并打印切片元素。如果传递的索引大于数组的长度，程序就会死机。

我们还有另一个函数**checkand printwistrecover**，它包含对

我们还有另一个函数**checkand printwistrecover**，它包含对

*   **用**延迟**功能，恢复**，也就是**处理关闭**

*   调用**检查和打印**功能

所以我们在函数**的开始有一个名为 **handleOutIfBounds** 的延迟函数【检查并打印与恢复】**。该函数包含如下的恢复函数调用

```
if r := recover(); r != nil {
    fmt.Println("Recovering from panic:", r)
}
```

**checkAndPrint** 功能引起恐慌，但没有恢复功能，而是调用 **checkAndPrintWithRecover** 功能进行恢复。我们将索引 2 传递给超出索引范围的**检查和打印**功能。因此**检查和打印**引发了恐慌，但是从输出中可以看到，程序仍然能够从恐慌中恢复。这是因为恐慌可以在被调用的函数中恢复，随后也可以在调用链中恢复