# Go (Golang)中恢复恐慌时函数的返回值

> 原文:[https://golangbyexample . com/return-value-function-慌张-recover-go/](https://golangbyexample.com/return-value-function-panic-recover-go/)

# **概述**

当恐慌恢复时，恐慌函数的返回值将是恐慌函数返回类型的默认值

# **程序**

让我们为它看一个程序

```
package main
import (
    "fmt"
)
func main() {
    a := []int{5, 6}
    val, err := checkAndGet(a, 2)
    fmt.Printf("Val: %d\n", val)
    fmt.Println("Error: ", err)
}
func checkAndGet(a []int, index int) (int, error) {
    defer handleOutOfBounds()
    if index > (len(a) - 1) {
        panic("Out of bound access for slice")
    }
    return a[index], nil
}
func handleOutOfBounds() {
    if r := recover(); r != nil {
        fmt.Println("Recovering from panic:", r)
    }
}
```

**输出**

```
Recovering from panic: Out of bound access for slice
Val: 0
Error: 
```

在上面的程序中，我们有**检查和获取**函数，该函数获取 int slice 中特定索引的值。如果传递给此函数的索引大于(slice-1 的长度)，则引发恐慌。还有一个 **handleOutOfBounds** 功能，用于从恐慌中恢复。因此，我们将索引 2 传递给**检查和获取**功能，它会引发恐慌，恐慌会在 **handleOutOfBounds** 功能中恢复。这就是为什么我们首先得到这个输出

```
Recovering from panic: Out of bound access for slice
```

请注意，在主函数中，我们像这样从**检查和获取**中回忆返回值

```
val, err := checkAndGet(a, 2)
```

**检查并获取**有两个返回值

*   （同 Internationalorganizations）国际组织
*   错误

由于**检查和获取**会产生恐慌，恐慌会在 handleOutOfBounds 函数中恢复，因此**检查和获取**的返回值将是其类型的默认值。

因此

```
fmt.Printf("Val: %d\n", val)
```

输出

```
Val: 0
```

因为零是 **int** 类型的默认值。

和

```
fmt.Println("Error: ", err)
```

输出

```
Error: 
```

因为 nil 是**错误**类型的默认值。

如果不想返回类型的默认零值，那么可以使用命名返回值。让我们来看看这个节目。

```
package main
import (
    "fmt"
)
func main() {
    a := []int{5, 6}
    val, err := checkAndGet(a, 2)
    fmt.Printf("Val: %d\n", val)
    fmt.Println("Error: ", err)
}
func checkAndGet(a []int, index int) (value int, err error) {
    value = 10
    defer handleOutOfBounds()
    if index > (len(a) - 1) {
        panic("Out of bound access for slice")
    }
    value = a[index]
    return value, nil
}
func handleOutOfBounds() {
    if r := recover(); r != nil {
        fmt.Println("Recovering from panic:", r)
    }
}
```

**输出**

```
Recovering from panic: Out of bound access for slice
Val: 10
Error: 
```

这个程序和之前的程序一样，唯一的区别是我们在 **checkAndGet** 函数中使用了命名返回值。

```
func checkAndGet(a []int, index int) (value int, err error)
```

我们在**检查和获取**功能中将命名返回值设置为 10

```
value = 10
```

这就是为什么我们在这个程序中得到下面的输出，因为恐慌产生了，它被恢复了

```
Recovering from panic: Out of bound access for slice
Val: 10
Error: 
```

还要注意，如果在程序中不会产生恐慌，那么它会在索引处输出正确的值。