# 围棋中的恢复功能示例

> 原文:[https://golangbyexample.com/recover-example-go/](https://golangbyexample.com/recover-example-go/)

# **概述**

Go 提供了一个内置功能 **recover** 用于从恐慌中恢复。下面是这个函数的签名

```go
func recover() interface{}
```

**延迟**功能是唯一在**恐慌**后调用的功能。所以将**恢复**功能置于**延迟**功能中是有意义的。如果**恢复**功能不在延迟功能内，则不会停止**死机**。

# **例**

让我们看一个恢复的例子

```go
package main

import "fmt"

func main() {

	a := []string{"a", "b"}
	checkAndPrint(a, 2)
	fmt.Println("Exiting normally")
}

func checkAndPrint(a []string, index int) {
	defer handleOutOfBounds()
	if index > (len(a) - 1) {
		panic("Out of bound access for slice")
	}
	fmt.Println(a[index])
}

func handleOutOfBounds() {
	if r := recover(); r != nil {
		fmt.Println("Recovering from panic:", r)
	}
}
```

**输出**

```go
Recovering from panic: Out of bound access for slice
Exiting normally
```

在上面的程序中，我们有一个函数 **checkAndPrint** ，它在参数中传递的索引处检查并打印切片元素。如果传递的索引大于数组的长度，程序就会死机。我们还在函数**的开始处添加了一个名为 **handleOutIfBounds** 的延迟函数**。该函数包含如下的恢复函数调用

```go
if r := recover(); r != nil {
    fmt.Println("Recovering from panic:", r)
}
```

**恢复**功能会捕捉到恐慌，我们也可以打印恐慌的消息。

```go
Recovering from panic: Out of bound access for slice
```

恢复功能后，程序继续，控制返回到被调用的功能，这里是**主**。这就是为什么我们的输出为

```go
Exiting normally
```

恢复函数返回传递给紧急函数的值。因此，检查 recover 函数的返回值是一个很好的做法。如果返回值不是零，则没有发生恐慌，并且没有用恐慌调用恢复函数。这就是为什么我们在延迟函数**中有下面的代码**

```go
if r := recover(); r != nil 
```

这里如果 **r** 为零，那么恐慌就不会发生。因此，如果没有恐慌，那么呼吁恢复将返回零

请注意，如果延迟函数和恢复函数不是从恐慌函数中调用的，那么在这种情况下，恐慌也可以在被调用的函数中恢复。事实上，在调用栈链中，随后从恐慌中恢复是可能的。

让我们看一个例子

```go
package main

import "fmt"

func main() {
    a := []string{"a", "b"}
    checkAndPrintWithRecover(a, 2)
    fmt.Println("Exiting normally")
}
func checkAndPrintWithRecover(a []string, index int) {
    defer handleOutOfBounds()
    checkAndPrint(a, 2)
}
func checkAndPrint(a []string, index int) {
    if index > (len(a) - 1) {
        panic("Out of bound access for slice")
    }
    fmt.Println(a[index])
}
func handleOutOfBounds() {
    if r := recover(); r != nil {
        fmt.Println("Recovering from panic:", r)
    }
}
```

**输出**

```go
Recovering from panic: Out of bound access for slice
Exiting normally
```

除了我们有一个额外的函数**checkand printwistrecover**之外，上面的程序与之前的程序完全相同，该函数包含对

*   具有恢复功能的延迟功能，即**处理关闭**
*   调用**检查和打印**功能

**所以基本上 **checkAndPrint** 函数引发了恐慌但是没有 recover 函数相反调用 recover 在于 **checkAndPrintWithRecover** 函数。但是程序仍然能够从恐慌中恢复，因为恐慌也可以在被调用的函数中恢复，随后也可以在链中恢复**